<?xml version="1.0" ?>
<!-- =================================================================================== -->
<!-- |    This document was autogenerated by xacro from src/swerve_drive/urdf/swerve_drive.xacro | -->
<!-- |    EDITING THIS FILE BY HAND IS NOT RECOMMENDED                                 | -->
<!-- =================================================================================== -->
<robot name="swerve_drive" xmlns:controller="http://playerstage.sourceforge.net/gazebo/xmlschema/#controller" xmlns:interface="http://playerstage.sourceforge.net/gazebo/xmlschema/#interface" xmlns:sensor="http://playerstage.sourceforge.net/gazebo/xmlschema/#sensor" xmlns:xacro="http://www.ros.org/wiki/xacro">
  <link name="swerve_base_link"/>
  <joint name="swerve_base_joint" type="fixed">
    <parent link="swerve_base_link"/>
    <child link="xl430_steer"/>
    <origin xyz="0 0 0"/>
  </joint>
  <link name="xl430_steer">
    <visual>
      <origin rpy="0 3.14159265359 3.14159265359" xyz="0 0 0.018"/>
      <geometry>
        <mesh filename="package://swerve_drive/mesh/XL430.dae"/>
      </geometry>
    </visual>
    <collision>
      <origin rpy="0 3.14159265359 3.14159265359" xyz="0 0 0.018"/>
      <geometry>
        <mesh filename="package://swerve_drive/mesh/XL430.dae"/>
      </geometry>
    </collision>
  </link>
  <joint name="steer" type="revolute">
    <parent link="xl430_steer"/>
    <child link="xl430_bracket"/>
    <origin rpy="0 0 0" xyz="0 -0.0003 -0.0435"/>
    <axis xyz="0 0 -1"/>
    <limit effort="300" lower="-1.57" upper="1.57" velocity="0.1"/>
  </joint>
  <link name="xl430_bracket">
    <visual>
      <origin rpy="0 0 0" xyz="0 -0.001 0"/>
      <geometry>
        <mesh filename="package://swerve_drive/mesh/XL430_BRACKET.dae"/>
      </geometry>
    </visual>
    <collision>
      <origin rpy="0 0 0" xyz="0 -0.001 0"/>
      <geometry>
        <mesh filename="package://swerve_drive/mesh/XL430_BRACKET.dae"/>
      </geometry>
    </collision>
  </link>
  <joint name="bracket2drive" type="fixed">
    <parent link="xl430_bracket"/>
    <child link="xl430_drive"/>
    <origin xyz="0 0 0"/>
    <axis xyz="0 1 0"/>
  </joint>
  <link name="xl430_drive">
    <visual>
      <origin rpy="1.57079632679 3.14159265359 0" xyz="0 0.018 0.0"/>
      <geometry>
        <mesh filename="package://swerve_drive/mesh/XL430.dae"/>
      </geometry>
    </visual>
    <collision>
      <origin rpy="1.57079632679 3.14159265359 0" xyz="0 0.018 0.0"/>
      <geometry>
        <mesh filename="package://swerve_drive/mesh/XL430.dae"/>
      </geometry>
    </collision>
  </link>
  <joint name="drive" type="continuous">
    <parent link="xl430_drive"/>
    <child link="tb3_wheel"/>
    <origin rpy="0 0 0" xyz="0 0 0"/>
    <axis xyz="0 -1 0"/>
  </joint>
  <link name="tb3_wheel">
    <visual>
      <origin rpy="0 0 3.14159265359" xyz="0 -0.01 0"/>
      <geometry>
        <mesh filename="package://swerve_drive/mesh/TB3_WHEEL.dae"/>
      </geometry>
    </visual>
    <collision>
      <origin rpy="0 0 3.14159265359" xyz="0 -0.01 0"/>
      <geometry>
        <mesh filename="package://swerve_drive/mesh/TB3_WHEEL.dae"/>
      </geometry>
    </collision>
  </link>
</robot>

